Workbook

Sheet Samantekt
A1: Rekstrarfélög — úttektaryfirlit
A2: Tekið saman 2026-06-02 úr slokkvitaeki: úttektarskýrslur (viðhengi) + skoðunargögn búnaðar.
A4: Rekstrarfélag | B4: Engin gögn | C4: Vantar úttekt 2026 | D4: Óljóst | E4: Úttekt 2026 ✓ | F4: Alls
A5: Eignaumsjón | B5: =COUNTIFS('Allar byggingar'!$A$2:$A$47,$A5,'Allar byggingar'!$J$2:$J$47,B$4) | C5: =COUNTIFS('Allar byggingar'!$A$2:$A$47,$A5,'Allar byggingar'!$J$2:$J$47,C$4) | D5: =COUNTIFS('Allar byggingar'!$A$2:$A$47,$A5,'Allar byggingar'!$J$2:$J$47,D$4) | E5: =COUNTIFS('Allar byggingar'!$A$2:$A$47,$A5,'Allar byggingar'!$J$2:$J$47,E$4) | F5: =SUM(B5:E5)
A6: Rekstrarumsjón | B6: =COUNTIFS('Allar byggingar'!$A$2:$A$47,$A6,'Allar byggingar'!$J$2:$J$47,B$4) | C6: =COUNTIFS('Allar byggingar'!$A$2:$A$47,$A6,'Allar byggingar'!$J$2:$J$47,C$4) | D6: =COUNTIFS('Allar byggingar'!$A$2:$A$47,$A6,'Allar byggingar'!$J$2:$J$47,D$4) | E6: =COUNTIFS('Allar byggingar'!$A$2:$A$47,$A6,'Allar byggingar'!$J$2:$J$47,E$4) | F6: =SUM(B6:E6)
A7: Eignarekstur | B7: =COUNTIFS('Allar byggingar'!$A$2:$A$47,$A7,'Allar byggingar'!$J$2:$J$47,B$4) | C7: =COUNTIFS('Allar byggingar'!$A$2:$A$47,$A7,'Allar byggingar'!$J$2:$J$47,C$4) | D7: =COUNTIFS('Allar byggingar'!$A$2:$A$47,$A7,'Allar byggingar'!$J$2:$J$47,D$4) | E7: =COUNTIFS('Allar byggingar'!$A$2:$A$47,$A7,'Allar byggingar'!$J$2:$J$47,E$4) | F7: =SUM(B7:E7)
A8: Heimaleiga | B8: =COUNTIFS('Allar byggingar'!$A$2:$A$47,$A8,'Allar byggingar'!$J$2:$J$47,B$4) | C8: =COUNTIFS('Allar byggingar'!$A$2:$A$47,$A8,'Allar byggingar'!$J$2:$J$47,C$4) | D8: =COUNTIFS('Allar byggingar'!$A$2:$A$47,$A8,'Allar byggingar'!$J$2:$J$47,D$4) | E8: =COUNTIFS('Allar byggingar'!$A$2:$A$47,$A8,'Allar byggingar'!$J$2:$J$47,E$4) | F8: =SUM(B8:E8)
A9: Fjöleignir | B9: =COUNTIFS('Allar byggingar'!$A$2:$A$47,$A9,'Allar byggingar'!$J$2:$J$47,B$4) | C9: =COUNTIFS('Allar byggingar'!$A$2:$A$47,$A9,'Allar byggingar'!$J$2:$J$47,C$4) | D9: =COUNTIFS('Allar byggingar'!$A$2:$A$47,$A9,'Allar byggingar'!$J$2:$J$47,D$4) | E9: =COUNTIFS('Allar byggingar'!$A$2:$A$47,$A9,'Allar byggingar'!$J$2:$J$47,E$4) | F9: =SUM(B9:E9)
A10: Samtals | B10: =SUM(B5:B9) | C10: =SUM(C5:C9) | D10: =SUM(D5:D9) | E10: =SUM(E5:E9) | F10: =SUM(F5:F9)
A12: Hvernig á að lesa:
A13: • Árdálkar sýna fjölda tækja sem úttekt nær til það ár. Grænn reitur = úttektarskýrsla til í kerfinu (viðhengi); blár = aðeins skráð í búnaðarsögu.
A14: • «Engin gögn» = hvorki tæki né skýrsla — kanna sérstaklega (möguleg gleymd hús).
A15: • «Vantar úttekt 2026» = skýrsla/skoðun til 2024 eða 2025 en engin 2026 — bóka í ár.
A16: • «Næsta skoðun» rauð = liðin.
A17: • Aðgerðalisti-flipi sýnir aðeins hús sem þarf að sinna; ✔-dálkur til að haka við þegar lokið.
A18: • Athugið: kerfið geymir aðeins nýjustu skoðun hvers tækis í búnaðarsögu, svo skýrslu-viðhengin (græn) eru áreiðanlegri vísbending um úttekt fyrri ára.

Sheet Fundin gögn
A1: Fundin gögn úr Drive og tölvu — fyllir í eyður
A2: Margar „eyður“ reyndust skjalavandi, ekki þjónustugat: skýrslur/reikningar eru til en voru ekki skráð í appið.
A4: Bygging | B4: Rekstrarfélag | C4: Staða í app | D4: Fundin ár | E4: Tegund | F4: Hvar | G4: Niðurstaða
A5: Aflagrandi 40 | B5: Eignaumsjón | C5: engin gögn | D5: 2025 | E5: Reikningur | F5: Tölva (Downloads) | G5: Þjónustað 2025 — skýrslu vantar í app
A6: Bílskýli Dalseli 6-22 | B6: Eignaumsjón | C6: engin gögn | D6: — | E6: — | F6: — | G6: Ekkert fannst (Dalsel 12 er annað hús)
A7: Flétturimi 10-16 | B7: Eignaumsjón | C7: engin gögn | D7: 2024 | E7: Reikn. + skýrsla (ód.) | F7: Tölva | G7: Þjónustað 2024
A8: Flétturimi 16 | B8: Eignaumsjón | C8: engin gögn | D8: 2024 | E8: Reikningur | F8: Tölva | G8: Þjónustað 2024
A9: Maltakur 3 | B9: Eignaumsjón | C9: engin gögn | D9: — | E9: — | F9: — | G9: EKKERT fannst — kanna sérstaklega
A10: Tangabryggja 13-15 | B10: Eignaumsjón | C10: engin gögn | D10: 2023, 2024 | E10: Reikn. + skýrsla (ód.) | F10: Drive + tölva | G10: Þjónustað 2023–2024
A11: Ásholt 2 | B11: Eignaumsjón | C11: engin gögn | D11: 2023 | E11: Úttektarskýrsla | F11: Drive | G11: Úttekt des. 2023 (18 léttv.+3 CO2+13 slöngur)
A12: Álfaskeið 78-80 | B12: Eignaumsjón | C12: engin gögn | D12: 2024, 2026 | E12: Úttektarskýrslur | F12: Drive | G12: Úttekt 2024 og 2026 til — vantar í app
A13: Álfaskeið 82-84 | B13: Rekstrarumsjón | C13: engin gögn | D13: 2023 | E13: Úttektarskýrsla | F13: Drive (Álfaskeið 84) | G13: Úttekt ~2023
A14: Árskógar 1-3 | B14: Eignarekstur | C14: engin gögn | D14: 2025 | E14: Reikn./eindagi | F14: Drive (póstur) | G14: Líklega þjónustað 2025 (reikningur)
A15: Árskógar 6-8 | B15: Eignarekstur | C15: engin gögn | D15: 2025 | E15: Reikningur | F15: Drive + tölva | G15: Þjónustað 2025
... A24: Álfaskeið 98-100 | B24: Rekstrarumsjón | C24: úttekt 2026 ✓ | D24: 2024,2026 | E24: Úttektarskýrslur | F24: Drive | G24: Staðfest 2024 + 2026
A26: Aðeins Maltakur 3 og EA Law Practice fundust hvergi (engin skýrsla né reikningur) — raunveruleg göt. Þúfubarð 19 er með úttekt frá 2020 og löngu útrunnið.

Sheet Allar byggingar
A1: Rekstrarfélag | B1: Bygging | C1: Kennitala | D1: Fjöldi tækja | E1: Úttekt 2024 | F1: Úttekt 2025 | G1: Úttekt 2026 | H1: Skýrslur (skjöl) | I1: Næsta skoðun | J1: Staða | K1: Forgangur | L1: Athugasemd
A2: Eignaumsjón | B2: 17.júní Torg 1-7, húsfélag | C2: 5007070110 | D2: 7 | E2: 7 | F2: · | G2: · | H2: 2 | I2: 2027-04-15 | J2: Vantar úttekt 2026 | K2: 1 | L2: Úttekt liggur fyrir 2024/2025 en ekki 2026 — tímabært að bóka.
A3: Eignaumsjón | B3: Aflagrandi 40, húsfélag | C3: 6407891239 | E3: · | F3: · | G3: · | J3: Engin gögn | K3: 1 | L3: Hvorki tæki né úttektarskýrsla í kerfinu — kanna hvort húsið hafi verið þjónustað.
A4: Eignaumsjón | B4: Bílskýli Dalseli 6-22 | C4: 5010891769 | E4: · | F4: · | G4: · | J4: Engin gögn | K4: 1 | L4: Hvorki tæki né úttektarskýrsla í kerfinu — kanna hvort húsið hafi verið þjónustað.
A5: Eignaumsjón | B5: Bólstaðarhlíð 40, húsfélag | C5: 4410872769 | D5: 2 | E5: 2 | F5: 2 | G5: 2 | H5: 4 | I5: 2027-02-15 | J5: Úttekt 2026 ✓ | K5: 3
A6: Eignaumsjón | B6: Dofraberg 11, húsfélag | C6: 4309901019 | D6: 9 | E6: · | F6: 9 | G6: · | H6: 2 | I6: 2026-11-15 | J6: Vantar úttekt 2026 | K6: 1 | L6: Úttekt liggur fyrir 2024/2025 en ekki 2026 — tímabært að bóka.
A7: Eignaumsjón | B7: Flétturimi 10-16, húsfélag | C7: 4902120190 | E7: · | F7: · | G7: · | J7: Engin gögn | K7: 1 | L7: Hvorki tæki né úttektarskýrsla í kerfinu — kanna hvort húsið hafi verið þjónustað.
A8: Eignaumsjón | B8: Flétturimi 16, húsfélag | C8: 6104932389 | E8: · | F8: · | G8: · | J8: Engin gögn | K8: 1 | L8: Hvorki tæki né úttektarskýrsla í kerfinu — kanna hvort húsið hafi verið þjónustað.
A9: Eignaumsjón | B9: Hverfisgata 40, húsfélag | C9: 6611191520 | D9: 42 | E9: · | F9: 42 | G9: 42 | H9: 3 | I9: 2027-01-15 | J9: Úttekt 2026 ✓ | K9: 3
A10: Eignaumsjón | B10: Húsfélagið Skipholti 50b | C10: 4702891989 | D10: 16 | E10: · | F10: · | G10: · | I10: 2027-03-15 | J10: Óljóst | K10: 2
A11: Eignaumsjón | B11: Kirkjulundur 12-14, húsfélag | C11: 6105140300 | D11: 15 | E11: 15 | F11: · | G11: · | H11: 4 | I11: 2026-11-15 | J11: Vantar úttekt 2026 | K11: 1 | L11: Úttekt liggur fyrir 2024/2025 en ekki 2026 — tímabært að bóka.
A12: Eignaumsjón | B12: Kórsalir 3, húsfélag | C12: 4404023480 | E12: ✓ | F12: · | G12: · | H12: 1 | J12: Vantar úttekt 2026 | K12: 1 | L12: Úttekt liggur fyrir 2024/2025 en ekki 2026 — tímabært að bóka.
A13: Eignaumsjón | B13: Maltakur 3, húsfélag | C13: 5612090570 | E13: · | F13: · | G13: · | J13: Engin gögn | K13: 1 | L13: Hvorki tæki né úttektarskýrsla í kerfinu — kanna hvort húsið hafi verið þjónustað.
A14: Eignaumsjón | B14: Seljabraut 42, húsfélag | C14: 5009760129 | D14: 6 | E14: · | F14: 6 | G14: · | H14: 2 | I14: 2026-12-15 | J14: Vantar úttekt 2026 | K14: 1 | L14: Úttekt liggur fyrir 2024/2025 en ekki 2026 — tímabært að bóka.
A15: Eignaumsjón | B15: Skaftahlíð 4-10, húsfélag | C15: 6811780159 | D15: 27 | E15: 27 | F15: · | G15: · | I15: 2025-04-15 | J15: Vantar úttekt 2026 | K15: 1 | L15: Úttekt liggur fyrir 2024/2025 en ekki 2026 — tímabært að bóka. Næsta skoðun liðin.
A16: Eignaumsjón | B16: Stigahlíð 26, húsfélag | C16: 4406992869 | D16: 10 | E16: 10 | F16: 10 | G16: · | H16: 3 | I16: 2026-11-15 | J16: Vantar úttekt 2026 | K16: 1 | L16: Úttekt liggur fyrir 2024/2025 en ekki 2026 — tímabært að bóka.
A17: Eignaumsjón | B17: Suðurhraun 10, rekstrarfélag | C17: 5203240700 | E17: ✓ | F17: · | G17: · | H17: 4 | J17: Vantar úttekt 2026 | K17: 1 | L17: Úttekt liggur fyrir 2024/2025 en ekki 2026 — tímabært að bóka.
A18: Eignaumsjón | B18: Sóleyjarhlíð 1, húsfélag | C18: 4802962579 | D18: 2 | E18: · | F18: 2 | G18: · | H18: 4 | I18: 2026-12-15 | J18: Vantar úttekt 2026 | K18: 1 | L18: Úttekt liggur fyrir 2024/2025 en ekki 2026 — tímabært að bóka.
A19: Eignaumsjón | B19: Tangabryggja 13-15, húsfélag | C19: 5204190120 | E19: · | F19: · | G19: · | J19: Engin gögn | K19: 1 | L19: Hvorki tæki né úttektarskýrsla í kerfinu — kanna hvort húsið hafi verið þjónustað.
A20: Eignaumsjón | B20: Tjarnarból 2, húsfélag | C20: 6009740179 | D20: 10 | E20: 10 | F20: 10 | G20: · | H20: 4 | I20: 2026-07-15 | J20: Vantar úttekt 2026 | K20: 1 | L20: Úttekt liggur fyrir 2024/2025 en ekki 2026 — tímabært að bóka.
A21: Eignaumsjón | B21: Tjarnarból 6, húsfélag | C21: 5710872199 | D21: 6 | E21: · | F21: 6 | G21: · | H21: 1 | I21: 2026-07-15 | J21: Vantar úttekt 2026 | K21: 1 | L21: Úttekt liggur fyrir 2024/2025 en ekki 2026 — tímabært að bóka.
A22: Eignaumsjón | B22: Torfufell 50, húsfélag | C22: 4810741349 | D22: 7 | E22: · | F22: 7 | G22: · | H22: 2 | I22: 2026-11-15 | J22: Vantar úttekt 2026 | K22: 1 | L22: Úttekt liggur fyrir 2024/2025 en ekki 2026 — tímabært að bóka.
A23: Eignaumsjón | B23: Tungusel 1-7, húsfélag | C23: 5606171190 | D23: 3 | E23: · | F23: 3 | G23: · | I23: 2026-05-15 | J23: Vantar úttekt 2026 | K23: 1 | L23: Úttekt liggur fyrir 2024/2025 en ekki 2026 — tímabært að bóka. Næsta skoðun liðin.
A24: Eignaumsjón | B24: Álfaskeið 78-80, húsfélag | C24: 4210081240 | D24: 11 | E24: · | F24: · | G24: · | I24: 2027-02-15 | J24: Óljóst | K24: 2
A25: Eignaumsjón | B25: Álfholt 2a,b,c, húsfélag | C25: 4409003210 | D25: 2 | E25: · | F25: 2 | G25: · | H25: 2 | I25: 2026-12-15 | J25: Vantar úttekt 2026 | K25: 1 | L25: Úttekt liggur fyrir 2024/2025 en ekki 2026 — tímabært að bóka.
A26: Eignaumsjón | B26: Álftamýri 24-30, húsfélag | C26: 6201850439 | D26: 51 | E26: · | F26: · | G26: 51 | H26: 5 | I26: 2027-02-15 | J26: Úttekt 2026 ✓ | K26: 3
A27: Eignaumsjón | B27: Ásholt 2, húsfélag | C27: 5303911089 | E27: · | F27: · | G27: · | J27: Engin gögn | K27: 1 | L27: Hvorki tæki né úttektarskýrsla í kerfinu — kanna hvort húsið hafi verið þjónustað.
A28: Rekstrarumsjón | B28: Burknavellir 5, húsfélag | C28: 5903043440 | E28: ✓ | F28: · | G28: · | H28: 3 | J28: Vantar úttekt 2026 | K28: 1 | L28: Úttekt liggur fyrir 2024/2025 en ekki 2026 — tímabært að bóka.
A29: Rekstrarumsjón | B29: Dofraberg 11, húsfélag | C29: 4309901019 | D29: 9 | E29: · | F29: 9 | G29: · | H29: 2 | I29: 2026-11-15 | J29: Vantar úttekt 2026 | K29: 1 | L29: Úttekt liggur fyrir 2024/2025 en ekki 2026 — tímabært að bóka.
A30: Rekstrarumsjón | B30: Eskivellir 1, húsfélag | C30: 6706061980 | D30: 11 | E30: 11 | F30: 11 | G30: · | H30: 5 | I30: 2026-05-15 | J30: Vantar úttekt 2026 | K30: 1 | L30: Úttekt liggur fyrir 2024/2025 en ekki 2026 — tímabært að bóka. Næsta skoðun liðin.
A31: Rekstrarumsjón | B31: Eskivellir 5, húsfélag | C31: 5312050490 | D31: 6 | E31: · | F31: 6 | G31: · | H31: 1 | I31: 2026-07-15 | J31: Vantar úttekt 2026 | K31: 1 | L31: Úttekt liggur fyrir 2024/2025 en ekki 2026 — tímabært að bóka.
A32: Rekstrarumsjón | B32: Sóleyjarhlíð 1, húsfélag | C32: 4802962579 | D32: 2 | E32: · | F32: 2 | G32: · | H32: 4 | I32: 2026-12-15 | J32: Vantar úttekt 2026 | K32: 1 | L32: Úttekt liggur fyrir 2024/2025 en ekki 2026 — tímabært að bóka.
A33: Rekstrarumsjón | B33: Álfaskeið 82-84, húsfélag | C33: 4710023050 | E33: · | F33: · | G33: · | J33: Engin gögn | K33: 1 | L33: Hvorki tæki né úttektarskýrsla í kerfinu — kanna hvort húsið hafi verið þjónustað.
A34: Rekstrarumsjón | B34: Álfaskeið 98-100, húsfélag | C34: 5311750859 | D34: 12 | E34: · | F34: · | G34: 12 | I34: 2027-04-20 | J34: Úttekt 2026 ✓ | K34: 3
A35: Rekstrarumsjón | B35: Álftahólar 4, húsfélag | C35: 4704868139 | D35: 17 | E35: · | F35: 17 | G35: 17 | H35: 3 | I35: 2027-02-15 | J35: Úttekt 2026 ✓ | K35: 3
A36: Eignarekstur | B36: Furugrund 73, húsfélag | C36: 4804867309 | D36: 12 | E36: · | F36: 12 | G36: 12 | H36: 7 | I36: 2026-05-15 | J36: Úttekt 2026 ✓ | K36: 1 | L36: Næsta skoðun liðin.
A37: Eignarekstur | B37: Húsfélagið Bæjarlind 12 | C37: 6301032310 | D37: 20 | E37: · | F37: 20 | G37: · | H37: 4 | I37: 2026-06-15 | J37: Vantar úttekt 2026 | K37: 1 | L37: Úttekt liggur fyrir 2024/2025 en ekki 2026 — tímabært að bóka.
A38: Eignarekstur | B38: Árskógar 1-3, húsfélag | C38: 5208190290 | E38: · | F38: · | G38: · | J38: Engin gögn | K38: 1 | L38: Hvorki tæki né úttektarskýrsla í kerfinu — kanna hvort húsið hafi verið þjónustað.
A39: Eignarekstur | B39: Árskógar 6-8, húsfélag | C39: 5102932079 | E39: · | F39: · | G39: · | J39: Engin gögn | K39: 1 | L39: Hvorki tæki né úttektarskýrsla í kerfinu — kanna hvort húsið hafi verið þjónustað.
A40: Eignarekstur | B40: Þverholt 24, húsfélag | C40: 6009911169 | D40: 5 | E40: 5 | F40: 5 | G40: · | H40: 3 | I40: 2026-10-15 | J40: Vantar úttekt 2026 | K40: 1 | L40: Úttekt liggur fyrir 2024/2025 en ekki 2026 — tímabært að bóka.
...

Sheet Aðgerðalisti
A1: Forgangur | B1: Rekstrarfélag | C1: Bygging | D1: Kennitala | E1: Staða | F1: Tæki | G1: 2024 | H1: 2025 | I1: 2026 | J1: Næsta skoðun | K1: Athugasemd | L1: Lokið?
A2: HÁR | B2: Eignarekstur | C2: Furugrund 73, húsfélag | D2: 4804867309 | E2: Úttekt 2026 ✓ | F2: 12 | G2: – | H2: ⚙12 | I2: 📄12 | J2: 2026-05-15 | K2: Næsta skoðun liðin.
A3: HÁR | B3: Eignarekstur | C3: Húsfélagið Bæjarlind 12 | D3: 6301032310 | E3: Vantar úttekt 2026 | F3: 20 | G3: – | H3: 📄20 | I3: – | J3: 2026-06-15 | K3: Úttekt liggur fyrir 2024/2025 en ekki 2026 — tímabært að bóka.
A4: HÁR | B4: Eignarekstur | C4: Árskógar 1-3, húsfélag | D4: 5208190290 | E4: Engin gögn | G4: – | H4: – | I4: – | K4: Hvorki tæki né úttektarskýrsla í kerfinu — kanna hvort húsið hafi verið þjónustað.
A5: HÁR | B5: Eignarekstur | C5: Árskógar 6-8, húsfélag | D5: 5102932079 | E5: Engin gögn | G5: – | H5: – | I5: – | K5: Hvorki tæki né úttektarskýrsla í kerfinu — kanna hvort húsið hafi verið þjónustað.
A6: HÁR | B6: Eignarekstur | C6: Þverholt 24, húsfélag | D6: 6009911169 | E6: Vantar úttekt 2026 | F6: 5 | G6: 📄5 | H6: 📄5 | I6: – | J6: 2026-10-15 | K6: Úttekt liggur fyrir 2024/2025 en ekki 2026 — tímabært að bóka.
A7: HÁR | B7: Eignaumsjón | C7: 17.júní Torg 1-7, húsfélag | D7: 5007070110 | E7: Vantar úttekt 2026 | F7: 7 | G7: 📄7 | H7: – | I7: – | J7: 2027-04-15 | K7: Úttekt liggur fyrir 2024/2025 en ekki 2026 — tímabært að bóka.
A8: HÁR | B8: Eignaumsjón | C8: Aflagrandi 40, húsfélag | D8: 6407891239 | E8: Engin gögn | G8: – | H8: – | I8: – | K8: Hvorki tæki né úttektarskýrsla í kerfinu — kanna hvort húsið hafi verið þjónustað.
A9: HÁR | B9: Eignaumsjón | C9: Bílskýli Dalseli 6-22 | D9: 5010891769 | E9: Engin gögn | G9: – | H9: – | I9: – | K9: Hvorki tæki né úttektarskýrsla í kerfinu — kanna hvort húsið hafi verið þjónustað.
A10: HÁR | B10: Eignaumsjón | C10: Dofraberg 11, húsfélag | D10: 4309901019 | E10: Vantar úttekt 2026 | F10: 9 | G10: – | H10: 📄9 | I10: – | J10: 2026-11-15 | K10: Úttekt liggur fyrir 2024/2025 en ekki 2026 — tímabært að bóka.
A11: HÁR | B11: Eignaumsjón | C11: Flétturimi 10-16, húsfélag | D11: 4902120190 | E11: Engin gögn | G11: – | H11: – | I11: – | K11: Hvorki tæki né úttektarskýrsla í kerfinu — kanna hvort húsið hafi verið þjónustað.
A12: HÁR | B12: Eignaumsjón | C12: Flétturimi 16, húsfélag | D12: 6104932389 | E12: Engin gögn | G12: – | H12: – | I12: – | K12: Hvorki tæki né úttektarskýrsla í kerfinu — kanna hvort húsið hafi verið þjónustað.
A13: HÁR | B13: Eignaumsjón | C13: Kirkjulundur 12-14, húsfélag | D13: 6105140300 | E13: Vantar úttekt 2026 | F13: 15 | G13: 📄15 | H13: – | I13: – | J13: 2026-11-15 | K13: Úttekt liggur fyrir 2024/2025 en ekki 2026 — tímabært að bóka.
A14: HÁR | B14: Eignaumsjón | C14: Kórsalir 3, húsfélag | D14: 4404023480 | E14: Vantar úttekt 2026 | G14: 📄 | H14: – | I14: – | K14: Úttekt liggur fyrir 2024/2025 en ekki 2026 — tímabært að bóka.
A15: HÁR | B15: Eignaumsjón | C15: Maltakur 3, húsfélag | D15: 5612090570 | E15: Engin gögn | G15: – | H15: – | I15: – | K15: Hvorki tæki né úttektarskýrsla í kerfinu — kanna hvort húsið hafi verið þjónustað.
A16: HÁR | B16: Eignaumsjón | C16: Seljabraut 42, húsfélag | D16: 5009760129 | E16: Vantar úttekt 2026 | F16: 6 | G16: – | H16: 📄6 | I16: – | J16: 2026-12-15 | K16: Úttekt liggur fyrir 2024/2025 en ekki 2026 — tímabært að bóka.
A17: HÁR | B17: Eignaumsjón | C17: Skaftahlíð 4-10, húsfélag | D17: 6811780159 | E17: Vantar úttekt 2026 | F17: 27 | G17: ⚙27 | H17: – | I17: – | J17: 2025-04-15 | K17: Úttekt liggur fyrir 2024/2025 en ekki 2026 — tímabært að bóka. Næsta skoðun liðin.
A18: HÁR | B18: Eignaumsjón | C18: Stigahlíð 26, húsfélag | D18: 4406992869 | E18: Vantar úttekt 2026 | F18: 10 | G18: 📄10 | H18: 📄10 | I18: – | J18: 2026-11-15 | K18: Úttekt liggur fyrir 2024/2025 en ekki 2026 — tímabært að bóka.
A19: HÁR | B19: Eignaumsjón | C19: Suðurhraun 10, rekstrarfélag | D19: 5203240700 | E19: Vantar úttekt 2026 | G19: 📄 | H19: – | I19: – | K19: Úttekt liggur fyrir 2024/2025 en ekki 2026 — tímabært að bóka.
A20: HÁR | B20: Eignaumsjón | C20: Sóleyjarhlíð 1, húsfélag | D20: 4802962579 | E20: Vantar úttekt 2026 | F20: 2 | G20: – | H20: 📄2 | I20: – | J20: 2026-12-15 | K20: Úttekt liggur fyrir 2024/2025 en ekki 2026 — tímabært að bóka.
A21: HÁR | B21: Eignaumsjón | C21: Tangabryggja 13-15, húsfélag | D21: 5204190120 | E21: Engin gögn | G21: – | H21: – | I21: – | K21: Hvorki tæki né úttektarskýrsla í kerfinu — kanna hvort húsið hafi verið þjónustað.
A22: HÁR | B22: Eignaumsjón | C22: Tjarnarból 2, húsfélag | D22: 6009740179 | E22: Vantar úttekt 2026 | F22: 10 | G22: 📄10 | H22: 📄10 | I22: – | J22: 2026-07-15 | K22: Úttekt liggur fyrir 2024/2025 en ekki 2026 — tímabært að bóka.
A23: HÁR | B23: Eignaumsjón | C23: Tjarnarból 6, húsfélag | D23: 5710872199 | E23: Vantar úttekt 2026 | F23: 6 | G23: – | H23: 📄6 | I23: – | J23: 2026-07-15 | K23: Úttekt liggur fyrir 2024/2025 en ekki 2026 — tímabært að bóka.
A24: HÁR | B24: Eignaumsjón | C24: Torfufell 50, húsfélag | D24: 4810741349 | E24: Vantar úttekt 2026 | F24: 7 | G24: – | H24: 📄7 | I24: – | J24: 2026-11-15 | K24: Úttekt liggur fyrir 2024/2025 en ekki 2026 — tímabært að bóka.
A25: HÁR | B25: Eignaumsjón | C25: Tungusel 1-7, húsfélag | D25: 5606171190 | E25: Vantar úttekt 2026 | F25: 3 | G25: – | H25: ⚙3 | I25: – | J25: 2026-05-15 | K25: Úttekt liggur fyrir 2024/2025 en ekki 2026 — tímabært að bóka. Næsta skoðun liðin.
A26: HÁR | B26: Eignaumsjón | C26: Álfholt 2a,b,c, húsfélag | D26: 4409003210 | E26: Vantar úttekt 2026 | F26: 2 | G26: – | H26: 📄2 | I26: – | J26: 2026-12-15 | K26: Úttekt liggur fyrir 2024/2025 en ekki 2026 — tímabært að bóka.
A27: HÁR | B27: Eignaumsjón | C27: Ásholt 2, húsfélag | D27: 5303911089 | E27: Engin gögn | G27: – | H27: – | I27: – | K27: Hvorki tæki né úttektarskýrsla í kerfinu — kanna hvort húsið hafi verið þjónustað.
A28: HÁR | B28: Fjöleignir | C28: Gullsmári 11, húsfélag | D28: 5605952559 | E28: Engin gögn | G28: – | H28: – | I28: – | K28: Hvorki tæki né úttektarskýrsla í kerfinu — kanna hvort húsið hafi verið þjónustað.
A29: HÁR | B29: Fjöleignir | C29: Háaleitisbraut 54, húsfélag | D29: 4511901569 | E29: Engin gögn | G29: – | H29: – | I29: – | K29: Hvorki tæki né úttektarskýrsla í kerfinu — kanna hvort húsið hafi verið þjónustað.
A30: HÁR | B30: Fjöleignir | C30: Þúfubarð 19, húsfélag | D30: 4701912019 | E30: Engin gögn | G30: – | H30: – | I30: – | K30: Hvorki tæki né úttektarskýrsla í kerfinu — kanna hvort húsið hafi verið þjónustað.
A31: HÁR | B31: Heimaleiga | C31: Aegina ehf. | D31: 6810130830 | E31: Engin gögn | G31: – | H31: – | I31: – | K31: Hvorki tæki né úttektarskýrsla í kerfinu — kanna hvort húsið hafi verið þjónustað.
A32: HÁR | B32: Heimaleiga | C32: EA Law Practice ehf. | D32: 6502220400 | E32: Engin gögn | G32: – | H32: – | I32: – | K32: Hvorki tæki né úttektarskýrsla í kerfinu — kanna hvort húsið hafi verið þjónustað.
A33: HÁR | B33: Heimaleiga | C33: Húsfélagið Laugavegi 42 | D33: 6110962599 | E33: Engin gögn | G33: – | H33: – | I33: – | K33: Hvorki tæki né úttektarskýrsla í kerfinu — kanna hvort húsið hafi verið þjónustað.
A34: HÁR | B34: Rekstrarumsjón | C34: Burknavellir 5, húsfélag | D34: 5903043440 | E34: Vantar úttekt 2026 | G34: 📄 | H34: – | I34: – | K34: Úttekt liggur fyrir 2024/2025 en ekki 2026 — tímabært að bóka.
A35: HÁR | B35: Rekstrarumsjón | C35: Dofraberg 11, húsfélag | D35: 4309901019 | E35: Vantar úttekt 2026 | F35: 9 | G35: – | H35: 📄9 | I35: – | J35: 2026-11-15 | K35: Úttekt liggur fyrir 2024/2025 en ekki 2026 — tímabært að bóka.
A36: HÁR | B36: Rekstrarumsjón | C36: Eskivellir 1, húsfélag | D36: 6706061980 | E36: Vantar úttekt 2026 | F36: 11 | G36: 📄11 | H36: 📄11 | I36: – | J36: 2026-05-15 | K36: Úttekt liggur fyrir 2024/2025 en ekki 2026 — tímabært að bóka. Næsta skoðun liðin.
A37: HÁR | B37: Rekstrarumsjón | C37: Eskivellir 5, húsfélag | D37: 5312050490 | E37: Vantar úttekt 2026 | F37: 6 | G37: – | H37: 📄6 | I37: – | J37: 2026-07-15 | K37: Úttekt liggur fyrir 2024/2025 en ekki 2026 — tímabært að bóka.
A38: HÁR | B38: Rekstrarumsjón | C38: Sóleyjarhlíð 1, húsfélag | D38: 4802962579 | E38: Vantar úttekt 2026 | F38: 2 | G38: – | H38: 📄2 | I38: – | J38: 2026-12-15 | K38: Úttekt liggur fyrir 2024/2025 en ekki 2026 — tímabært að bóka.
A39: HÁR | B39: Rekstrarumsjón | C39: Álfaskeið 82-84, húsfélag | D39: 4710023050 | E39: Engin gögn | G39: – | H39: – | I39: – | K39: Hvorki tæki né úttektarskýrsla í kerfinu — kanna hvort húsið hafi verið þjónustað.
A40: Miðlungs | B40: Eignaumsjón | C40: Húsfélagið Skipholti 50b | D40: 4702891989 | E40: Óljóst | F40: 16 | G40: – | H40: – | I40: – | J40: 2027-03-15
...
